// Bug happens on JVM 
// WITH_RUNTIME
// FILE: tmp0.kt


val prope1 = try {}
catch(e: ArithmeticException){
{x -> 
}
}

